Workbook

Sheet Instructions
B2: empeo Registration — Automation Test Report (Gofive · Automate Tester Exam 1.0)
B3: Candidate: Newyear (Yatichapat Kanta) · Role: Automate QA Engineer (Gofive online assessment, part 6) · 27 Oct 2026
B5: How this workbook is organized
B6: • | C6: Test Plan & Summary — project info, scope, test data, and an auto-calculated Pass/Fail dashboard per module (do not edit the dashboard formulas).
B7: • | C7: Test Cases — one flat, filterable table: 24 scenarios across 5 modules (Registration form, OTP verification, Promo code, Validation / error handling, Edge cases – phone), one row per step.
B8: • | C8: Bug Report — 6 findings observed on UAT (UX gaps, items that need PO confirmation, and an intermittent slow redirect), each with steps, evidence and the related test case.
B9: • | C9: Picture - Evidence — every screenshot with a preview and a link (GitHub repo docs/), plus links to the videos and the HTML report.
B11: How the Test Cases were executed
B12: • | C12: All scenarios were executed automatically with Playwright Test (JavaScript) on https://portal.uat.gofive.co.th/Register/empeo; each Scenario ID is also the automated test title, e.g. "TC-OTP-02 …".
B13: • | C13: Pass / Fail is filled ONLY on the LAST step row of each Scenario ID — this is what the Summary dashboard counts. Earlier steps show 'As expected' in Actual Result.
B14: • | C14: Pass / Fail comes from the final full run on the tester's machine (Windows 11, Chromium). Run history is in Test Plan & Summary.
B15: • | C15: 'Evidence' links open the screenshot on GitHub; the Remark column names the spec file › test, so the same case can be found in the HTML report.
B16: • | C16: Data-driven cases (e.g. TC-VAL-02 ×5, TC-PRM-02 ×3) are one scenario here but several automated runs: 24 scenarios = 35 automated runs.
B18: How bugs are logged
B19: • | C19: Every finding gets one row in Bug Report; none of the 35 automated checks fail on the final run, so the findings are UX / requirement / environment observations, not failed assertions.
B20: • | C20: 'Related Test Case' links back to the Scenario ID (e.g. 'TC-VAL-05') that shows the behaviour.
B21: • | C21: Status: 'Open' = behaviour to fix; 'Need clarification' = rule not defined in the brief (ask PO); 'Observed (intermittent)' = UAT timing issue.
B22: • | C22: 'Picture / Evidence' is a clickable link to the screenshot (GitHub) — same files as the Drive folder 'Evident Photo'.
B24: Color legend
B25: • | C25: Orange header = sheet header row.
B26: • | C26: Grey rows = alternate scenarios (readability only).
B27: • | C27: Green / Red in Pass-Fail cells = conditional formatting, updates automatically.
B29: Links
B30: • | C30: =HYPERLINK("https://github.com/Yatichapat6510/empeo-registration-tests","GitHub repository (code, README, test case docs): https://github.com/Yatichapat6510/empeo-registration-tests")
B31: • | C31: =HYPERLINK("https://drive.google.com/drive/folders/1X-i7e-JlTXuE6q1Cv5BMVRRIkGONhn_q","Google Drive folder (this workbook, Evident Photo, Video)")
B32: • | C32: =HYPERLINK("https://drive.google.com/file/d/15qjjIL-YVDhUihsYCpx1IiIzDr7kI9Cy/view","Video – headed run recorded on screen (Drive)")
B33: • | C33: =HYPERLINK("https://github.com/Yatichapat6510/empeo-registration-tests/blob/main/docs/demo/automation-run.mp4","Video – Playwright recording of all 35 tests, 8 min (GitHub docs/demo/automation-run.mp4)")
B34: • | C34: =HYPERLINK("https://github.com/Yatichapat6510/empeo-registration-tests/blob/main/README.md","README – how to run, design decisions, findings, assumptions")
B36: Test environment reference
B37: • | C37: Register page: https://portal.uat.gofive.co.th/Register/empeo (UAT, Thai UI)
B38: • | C38: Fixed test data from the brief: phone 0967690708 · OTP 123456 · promo code FREE15DAY
B39: • | C39: Other data is generated per test: unique company name + unique e-mail domain (the system allows one account per e-mail domain).
B40: • | C40: Run locally: npm ci → npx playwright install chromium → npx playwright test → npx playwright show-report

Sheet Test Plan & Summary
A1: Test Plan & Summary
A3: Project Name | B3: empeo – Free-trial Registration
A4: Document Name | B4: Test Scripts – Automation Tester Exam 1.0
A5: Candidate / Tester | B5: Newyear (Yatichapat Kanta)
A6: Role | B6: Automation Tester
A7: Created | B7: 27/10/2026
A8: Environment | B8: UAT https://portal.uat.gofive.co.th/Register/empeo · Windows 11 · Chromium (Playwright 1.64.1) · TH locale
A9: Test Data | B9: Phone 0967690708 · OTP 123456 · Promo FREE15DAY · other data generated per test (unique company + e-mail domain)
A10: Scope | B10: Successful registration, OTP verification, promo code validation, required fields & error handling, edge cases (invalid phone, expired OTP, reused promo)
A11: Out of scope | B11: Thai-company (tax ID lookup) path; real OTP expiry time; SMS delivery
A12: Automation | B12: Playwright Test 1.64 (JavaScript), POM + fixtures, 24 cases / 35 automated runs
A14: Dashboard
A15: Module | B15: Total Test Cases | C15: Pass | D15: Fail | E15: Blocked | F15: N/A | G15: Not Executed | H15: % Complete | I15: % Pass Rate
A16: Registration form | B16: =COUNTIFS('Test Cases'!$A$2:$A$89,A16,'Test Cases'!$K$2:$K$89,"<>") | C16: =COUNTIFS('Test Cases'!$A$2:$A$89,$A16,'Test Cases'!$K$2:$K$89,"Pass") | D16: =COUNTIFS('Test Cases'!$A$2:$A$89,$A16,'Test Cases'!$K$2:$K$89,"Fail") | E16: =COUNTIFS('Test Cases'!$A$2:$A$89,$A16,'Test Cases'!$K$2:$K$89,"Blocked") | F16: =COUNTIFS('Test Cases'!$A$2:$A$89,$A16,'Test Cases'!$K$2:$K$89,"N/A") | G16: =COUNTIFS('Test Cases'!$A$2:$A$89,$A16,'Test Cases'!$K$2:$K$89,"Not Executed") | H16: =IF(B16=0,0,(C16+D16+E16+F16)/B16) | I16: =IF((C16+D16)=0,0,C16/(C16+D16))
A17: OTP verification | B17: =COUNTIFS('Test Cases'!$A$2:$A$89,A17,'Test Cases'!$K$2:$K$89,"<>") | C17: =COUNTIFS('Test Cases'!$A$2:$A$89,$A17,'Test Cases'!$K$2:$K$89,"Pass") | D17: =COUNTIFS('Test Cases'!$A$2:$A$89,$A17,'Test Cases'!$K$2:$K$89,"Fail") | E17: =COUNTIFS('Test Cases'!$A$2:$A$89,$A17,'Test Cases'!$K$2:$K$89,"Blocked") | F17: =COUNTIFS('Test Cases'!$A$2:$A$89,$A17,'Test Cases'!$K$2:$K$89,"N/A") | G17: =COUNTIFS('Test Cases'!$A$2:$A$89,$A17,'Test Cases'!$K$2:$K$89,"Not Executed") | H17: =IF(B17=0,0,(C17+D17+E17+F17)/B17) | I17: =IF((C17+D17)=0,0,C17/(C17+D17))
A18: Promo code | B18: =COUNTIFS('Test Cases'!$A$2:$A$89,A18,'Test Cases'!$K$2:$K$89,"<>") | C18: =COUNTIFS('Test Cases'!$A$2:$A$89,$A18,'Test Cases'!$K$2:$K$89,"Pass") | D18: =COUNTIFS('Test Cases'!$A$2:$A$89,$A18,'Test Cases'!$K$2:$K$89,"Fail") | E18: =COUNTIFS('Test Cases'!$A$2:$A$89,$A18,'Test Cases'!$K$2:$K$89,"Blocked") | F18: =COUNTIFS('Test Cases'!$A$2:$A$89,$A18,'Test Cases'!$K$2:$K$89,"N/A") | G18: =COUNTIFS('Test Cases'!$A$2:$A$89,$A18,'Test Cases'!$K$2:$K$89,"Not Executed") | H18: =IF(B18=0,0,(C18+D18+E18+F18)/B18) | I18: =IF((C18+D18)=0,0,C18/(C18+D18))
A19: Validation / error handling | B19: =COUNTIFS('Test Cases'!$A$2:$A$89,A19,'Test Cases'!$K$2:$K$89,"<>") | C19: =COUNTIFS('Test Cases'!$A$2:$A$89,$A19,'Test Cases'!$K$2:$K$89,"Pass") | D19: =COUNTIFS('Test Cases'!$A$2:$A$89,$A19,'Test Cases'!$K$2:$K$89,"Fail") | E19: =COUNTIFS('Test Cases'!$A$2:$A$89,$A19,'Test Cases'!$K$2:$K$89,"Blocked") | F19: =COUNTIFS('Test Cases'!$A$2:$A$89,$A19,'Test Cases'!$K$2:$K$89,"N/A") | G19: =COUNTIFS('Test Cases'!$A$2:$A$89,$A19,'Test Cases'!$K$2:$K$89,"Not Executed") | H19: =IF(B19=0,0,(C19+D19+E19+F19)/B19) | I19: =IF((C19+D19)=0,0,C19/(C19+D19))
A20: Edge cases – phone | B20: =COUNTIFS('Test Cases'!$A$2:$A$89,A20,'Test Cases'!$K$2:$K$89,"<>") | C20: =COUNTIFS('Test Cases'!$A$2:$A$89,$A20,'Test Cases'!$K$2:$K$89,"Pass") | D20: =COUNTIFS('Test Cases'!$A$2:$A$89,$A20,'Test Cases'!$K$2:$K$89,"Fail") | E20: =COUNTIFS('Test Cases'!$A$2:$A$89,$A20,'Test Cases'!$K$2:$K$89,"Blocked") | F20: =COUNTIFS('Test Cases'!$A$2:$A$89,$A20,'Test Cases'!$K$2:$K$89,"N/A") | G20: =COUNTIFS('Test Cases'!$A$2:$A$89,$A20,'Test Cases'!$K$2:$K$89,"Not Executed") | H20: =IF(B20=0,0,(C20+D20+E20+F20)/B20) | I20: =IF((C20+D20)=0,0,C20/(C20+D20))
A21: Total | B21: =SUM(B16:B20) | C21: =SUM(C16:C20) | D21: =SUM(D16:D20) | E21: =SUM(E16:E20) | F21: =SUM(F16:F20) | G21: =SUM(G16:G20) | H21: =IF(B21=0,0,(C21+D21+E21+F21)/B21) | I21: =IF((C21+D21)=0,0,C21/(C21+D21))
A23: Run history (27/10/2026)
B24: 15:59 npx playwright test (4 workers) – 35 passed / 0 failed, 2.2 min
B25: 16:08 npm run test:video (video + trace for every test) – 35 passed / 0 failed, 4.0 min
B26: 16:47 npx playwright test (tester's run) – 33 passed / 2 failed: TC-OTP-01, TC-OTP-03 (redirect after OTP took > 10 s on UAT → BUG-06)
B27: Fix: wait for set-password page up to 30 s, dropdown/checkbox clicks retried, 1 retry on UAT (retries are reported as "flaky", not hidden)
B28: 17:13 FINAL – npx playwright test (2 workers, 1 retry) – 35 passed / 0 failed / 0 flaky, 3.0 min ← result used in Test Cases

Sheet Test Cases
A1: Module | B1: Scenario ID | C1: Type | D1: Scenario | E1: Step No | F1: Function | G1: Condition / Procedure | H1: Checking | I1: Expected Result | J1: Actual Result | K1: Pass / Fail | L1: Evidence (Screenshot) | M1: Tester | N1: Test Date | O1: Remark (automated test)
A2: Registration form | B2: TC-REG-01 | C2: Normal case | D2: Register with valid data + promo FREE15DAY, verify OTP, set password | E2: 01.1 | F2: Open page | G2: Open /Register/empeo | H2: Redirect Screen | I2: Registration form "ทดลองใช้งาน empeo ฟรี!" is shown | J2: As expected
A3: Registration form | B3: TC-REG-01 | C3: Normal case | E3: 01.2 | F3: Fill form | G3: Select "อื่นๆ"; company name (unique); business type "เทคโนโลยี"; users "1-20"; unique e-mail; first/last name; phone 0967690708; tick consent | H3: Fields for filling | I3: All fields accept the values, no error | J3: As expected
A4: Registration form | B4: TC-REG-01 | C4: Normal case | E4: 01.3 | F4: Promo code | G4: Click "ใช้โค้ดส่วนลด", enter FREE15DAY, click "ใช้โค้ด" | H4: Fields for filling / button | I4: Code shown as applied "FREE15DAY" | J4: As expected
A5: Registration form | B5: TC-REG-01 | C5: Normal case | E5: 01.4 | F5: Submit | G5: Click "ทดลองใช้ฟรี" | H5: Redirect Screen | I5: OTP dialog shows "…ส่งไปยัง 096-XXX-0708" and ref number; POST /api/v2/register has couponCode FREE15DAY | J5: As expected
A6: Registration form | B6: TC-REG-01 | C6: Normal case | E6: 01.5 | F6: Verify OTP | G6: Enter 123456, click "ยืนยัน" | H6: Redirect Screen | I6: Redirect to /Register/empeo/create-password?token=… | J6: As expected
A7: Registration form | B7: TC-REG-01 | C7: Normal case | E7: 01.6 | F7: Set password | G7: Enter QaAuto12345 in both fields, click "ตั้งรหัสผ่าน" | H7: Redirect Screen | I7: "empeo พร้อมใช้งานแล้ว!" and button "เริ่มต้นใช้งาน" shown | J7: As expected | K7: Pass | L7: =HYPERLINK("https://github.com/Yatichapat6510/empeo-registration-tests/blob/main/docs/exploration/19-after-password.png","19-after-password.png") | M7: Newyear (Yatichapat Kanta) | N7: 27/10/2026 | O7: registration.spec.js › TC-REG-01
A8: Registration form | B8: TC-REG-02 | C8: Normal case | D8: Register without promo code (optional field) | E8: 02.1 | F8: Open page | G8: Open /Register/empeo | H8: Redirect Screen | I8: Registration form "ทดลองใช้งาน empeo ฟรี!" is shown | J8: As expected
A9: Registration form | B9: TC-REG-02 | C9: Normal case | E9: 02.2 | F9: Fill form | G9: Select "อื่นๆ"; company name (unique); business type "เทคโนโลยี"; users "1-20"; unique e-mail; first/last name; phone 0967690708; tick consent | H9: Fields for filling | I9: All fields accept the values, no error | J9: As expected
A10: Registration form | B10: TC-REG-02 | C10: Normal case | E10: 02.3 | F10: Submit | G10: Click "ทดลองใช้ฟรี" | H10: Button / Redirect Screen | I10: OTP dialog "กรุณาตรวจสอบข้อความ" with 6 OTP boxes is shown | J10: As expected
A11: Registration form | B11: TC-REG-02 | C11: Normal case | E11: 02.4 | F11: Verify button | G11: Do not type OTP | H11: button | I11: "ยืนยัน" is disabled | J11: As expected | K11: Pass | L11: =HYPERLINK("https://github.com/Yatichapat6510/empeo-registration-tests/blob/main/docs/report/01-html-report-summary.jpg","HTML report (all tests)") | M11: Newyear (Yatichapat Kanta) | N11: 27/10/2026 | O11: registration.spec.js › TC-REG-02
A12: Registration form | B12: TC-REG-03 | C12: Error case | D12: Set-password rules (case, digit, 8+ chars, confirmation match) | E12: 03.1 | F12: Open page | G12: Open /Register/empeo | H12: Redirect Screen | I12: Registration form "ทดลองใช้งาน empeo ฟรี!" is shown | J12: As expected
A13: Registration form | B13: TC-REG-03 | C13: Error case | E13: 03.2 | F13: Fill form | G13: Select "อื่นๆ"; company name (unique); business type "เทคโนโลยี"; users "1-20"; unique e-mail; first/last name; phone 0967690708; tick consent | H13: Fields for filling | I13: All fields accept the values, no error | J13: As expected
A14: Registration form | B14: TC-REG-03 | C14: Error case | E14: 03.3 | F14: Submit | G14: Click "ทดลองใช้ฟรี" | H14: Button / Redirect Screen | I14: OTP dialog "กรุณาตรวจสอบข้อความ" with 6 OTP boxes is shown | J14: As expected
A15: Registration form | B15: TC-REG-03 | C15: Error case | E15: 03.4 | F15: Verify OTP | G15: Enter 123456, click "ยืนยัน" | H15: Redirect Screen | I15: Set-password page "กรุณาตั้งรหัสผ่าน" | J15: As expected
A16: Registration form | B16: TC-REG-03 | C16: Error case | E16: 03.5 | F16: Weak password | G16: Enter abc / abcdefgh / ABCDEFGH1 / Abcdefgh / Ab1 in both fields | H16: button | I16: "ตั้งรหัสผ่าน" disabled for each | J16: As expected
A17: Registration form | B17: TC-REG-03 | C17: Error case | E17: 03.6 | F17: Mismatch | G17: Password QaAuto12345, confirm QaAuto12345x, click "ตั้งรหัสผ่าน" | H17: Message / Redirect Screen | I17: "รหัสผ่านไม่ตรงกัน" shown; stays on set-password page | J17: As expected
A18: Registration form | B18: TC-REG-03 | C18: Error case | E18: 03.7 | F18: Valid password | G18: QaAuto12345 in both fields | H18: button | I18: "ตั้งรหัสผ่าน" enabled | J18: As expected | K18: Pass | L18: =HYPERLINK("https://github.com/Yatichapat6510/empeo-registration-tests/blob/main/docs/exploration/23-password-mismatch.png","23-password-mismatch.png") | M18: Newyear (Yatichapat Kanta) | N18: 27/10/2026 | O18: registration.spec.js › TC-REG-03
A19: OTP verification | B19: TC-OTP-01 | C19: Normal case | D19: Correct OTP 123456 | E19: 01.1 | F19: Open page | G19: Open /Register/empeo | H19: Redirect Screen | I19: Registration form "ทดลองใช้งาน empeo ฟรี!" is shown | J19: As expected
A20: OTP verification | B20: TC-OTP-01 | C20: Normal case | E20: 01.2 | F20: Fill form | G20: Select "อื่นๆ"; company name (unique); business type "เทคโนโลยี"; users "1-20"; unique e-mail; first/last name; phone 0967690708; tick consent | H20: Fields for filling | I20: All fields accept the values, no error | J20: As expected
A21: OTP verification | B21: TC-OTP-01 | C21: Normal case | E21: 01.3 | F21: Submit | G21: Click "ทดลองใช้ฟรี" | H21: Button / Redirect Screen | I21: OTP dialog "กรุณาตรวจสอบข้อความ" with 6 OTP boxes is shown | J21: As expected
A22: OTP verification | B22: TC-OTP-01 | C22: Normal case | E22: 01.4 | F22: Verify OTP | G22: Enter 123456, click "ยืนยัน" | H22: Redirect Screen | I22: Redirect to set-password page | J22: As expected | K22: Pass | L22: =HYPERLINK("https://github.com/Yatichapat6510/empeo-registration-tests/blob/main/docs/exploration/15-success.png","15-success.png") | M22: Newyear (Yatichapat Kanta) | N22: 27/10/2026 | O22: otp.spec.js › TC-OTP-01 · Failed once in run 16:47 (redirect after OTP > 10 s on UAT, see BUG-06); passed after wait 30 s + 1 retry
A23: OTP verification | B23: TC-OTP-02 | C23: Error case | D23: Wrong OTP | E23: 02.1 | F23: Open page | G23: Open /Register/empeo | H23: Redirect Screen | I23: Registration form "ทดลองใช้งาน empeo ฟรี!" is shown | J23: As expected
A24: OTP verification | B24: TC-OTP-02 | C24: Error case | E24: 02.2 | F24: Fill form | G24: Select "อื่นๆ"; company name (unique); business type "เทคโนโลยี"; users "1-20"; unique e-mail; first/last name; phone 0967690708; tick consent | H24: Fields for filling | I24: All fields accept the values, no error | J24: As expected
A25: OTP verification | B25: TC-OTP-02 | C25: Error case | E25: 02.3 | F25: Submit | G25: Click "ทดลองใช้ฟรี" | H25: Button / Redirect Screen | I25: OTP dialog "กรุณาตรวจสอบข้อความ" with 6 OTP boxes is shown | J25: As expected
A26: OTP verification | B26: TC-OTP-02 | C26: Error case | E26: 02.4 | F26: Verify OTP | G26: Enter 000000, click "ยืนยัน" | H26: Message | I26: Toast "OTP ไม่ถูกต้อง กรุณาลองใหม่อีกครั้ง"; dialog stays; OTP boxes cleared | J26: As expected | K26: Pass | L26: =HYPERLINK("https://github.com/Yatichapat6510/empeo-registration-tests/blob/main/docs/exploration/13-otp-wrong.png","13-otp-wrong.png") | M26: Newyear (Yatichapat Kanta) | N26: 27/10/2026 | O26: otp.spec.js › TC-OTP-02
A27: OTP verification | B27: TC-OTP-03 | C27: Normal case | D27: Retry with correct OTP after a wrong one | E27: 03.1 | F27: Open page | G27: Open /Register/empeo | H27: Redirect Screen | I27: Registration form "ทดลองใช้งาน empeo ฟรี!" is shown | J27: As expected
A28: OTP verification | B28: TC-OTP-03 | C28: Normal case | E28: 03.2 | F28: Fill form | G28: Select "อื่นๆ"; company name (unique); business type "เทคโนโลยี"; users "1-20"; unique e-mail; first/last name; phone 0967690708; tick consent | H28: Fields for filling | I28: All fields accept the values, no error | J28: As expected
A29: OTP verification | B29: TC-OTP-03 | C29: Normal case | E29: 03.3 | F29: Submit | G29: Click "ทดลองใช้ฟรี" | H29: Button / Redirect Screen | I29: OTP dialog "กรุณาตรวจสอบข้อความ" with 6 OTP boxes is shown | J29: As expected
A30: OTP verification | B30: TC-OTP-03 | C30: Normal case | E30: 03.4 | F30: Wrong OTP | G30: Enter 111111, click "ยืนยัน" | H30: Message | I30: Wrong-OTP toast | J30: As expected
A31: OTP verification | B31: TC-OTP-03 | C31: Normal case | E31: 03.5 | F31: Correct OTP | G31: Enter 123456, click "ยืนยัน" | H31: Redirect Screen | I31: Redirect to set-password page | J31: As expected | K31: Pass | L31: =HYPERLINK("https://github.com/Yatichapat6510/empeo-registration-tests/blob/main/docs/report/01-html-report-summary.jpg","HTML report (all tests)") | M31: Newyear (Yatichapat Kanta) | N31: 27/10/2026 | O31: otp.spec.js › TC-OTP-03 · Failed once in run 16:47 (redirect after OTP > 10 s on UAT, see BUG-06); passed after wait 30 s + 1 retry
A32: OTP verification | B32: TC-OTP-04 | C32: Error case | D32: Verify button needs all 6 digits | E32: 04.1 | F32: Open page | G32: Open /Register/empeo | H32: Redirect Screen | I32: Registration form "ทดลองใช้งาน empeo ฟรี!" is shown | J32: As expected
A33: OTP verification | B33: TC-OTP-04 | C33: Error case | E33: 04.2 | F33: Fill form | G33: Select "อื่นๆ"; company name (unique); business type "เทคโนโลยี"; users "1-20"; unique e-mail; first/last name; phone 0967690708; tick consent | H33: Fields for filling | I33: All fields accept the values, no error | J33: As expected
A34: OTP verification | B34: TC-OTP-04 | C34: Error case | E34: 04.3 | F34: Submit | G34: Click "ทดลองใช้ฟรี" | H34: Button / Redirect Screen | I34: OTP dialog "กรุณาตรวจสอบข้อความ" with 6 OTP boxes is shown | J34: As expected
A35: OTP verification | B35: TC-OTP-04 | C35: Error case | E35: 04.4 | F35: Partial OTP | G35: Type 12345 | H35: button | I35: "ยืนยัน" disabled | J35: As expected
A36: OTP verification | B36: TC-OTP-04 | C36: Error case | E36: 04.5 | F36: Full OTP | G36: Type 6 (6th digit) | H36: button | I36: "ยืนยัน" enabled | J36: As expected | K36: Pass | L36: =HYPERLINK("https://github.com/Yatichapat6510/empeo-registration-tests/blob/main/docs/report/01-html-report-summary.jpg","HTML report (all tests)") | M36: Newyear (Yatichapat Kanta) | N36: 27/10/2026 | O36: otp.spec.js › TC-OTP-04
A37: OTP verification | B37: TC-OTP-05 | C37: Edge case | D37: OTP accepts digits only | E37: 05.1 | F37: Open page | G37: Open /Register/empeo | H37: Redirect Screen | I37: Registration form "ทดลองใช้งาน empeo ฟรี!" is shown | J37: As expected
A38: OTP verification | B38: TC-OTP-05 | C38: Edge case | E38: 05.2 | F38: Fill form | G38: Select "อื่นๆ"; company name (unique); business type "เทคโนโลยี"; users "1-20"; unique e-mail; first/last name; phone 0967690708; tick consent | H38: Fields for filling | I38: All fields accept the values, no error | J38: As expected
A39: OTP verification | B39: TC-OTP-05 | C39: Edge case | E39: 05.3 | F39: Submit | G39: Click "ทดลองใช้ฟรี" | H39: Button / Redirect Screen | I39: OTP dialog "กรุณาตรวจสอบข้อความ" with 6 OTP boxes is shown | J39: As expected
A40: OTP verification | B40: TC-OTP-05 | C40: Edge case | E40: 05.4 | F40: Non-digits | G40: Type ab!@cd | H40: Fields for filling | I40: Boxes stay empty; "ยืนยัน" disabled | J40: As expected | K40: Pass | L40: =HYPERLINK("https://github.com/Yatichapat6510/empeo-registration-tests/blob/main/docs/report/01-html-report-summary.jpg","HTML report (all tests)") | M40: Newyear (Yatichapat Kanta) | N40: 27/10/2026 | O40: otp.spec.js › TC-OTP-05
...

Sheet Bug Report
A1: Incident No. | B1: Occurred Date | C1: Screen | D1: Related Test Case | E1: Raised by | F1: Checked by | G1: Priority | H1: Severity | I1: Status | J1: Detail (Description) | K1: Steps to Reproduce | L1: Expected Result | M1: Actual Result | N1: Picture / Evidence | O1: Environment | P1: Major Class | Q1: Minor Class | R1: Remark
A2: BUG-01 | B2: 27/10/2026 | C2: Registration form | D2: TC-VAL-05 | E2: Newyear (Yatichapat Kanta) | G2: Medium | H2: Minor | I2: Open | J2: Submitting without ticking the consent box does nothing and shows no message, so the user does not know why. | K2: 1. Open /Register/empeo 2. Fill all fields with valid data 3. Leave consent unticked 4. Click "ทดลองใช้ฟรี" | L2: A message asks the user to accept the policy/terms (or the button is disabled) | M2: Nothing happens; no message | N2: =HYPERLINK("https://github.com/Yatichapat6510/empeo-registration-tests/blob/main/docs/exploration/12-no-consent.png","12-no-consent.png") | O2: UAT · Chromium · TH | P2: UX | Q2: Validation message
A3: BUG-02 | B3: 27/10/2026 | C3: Set password | D3: TC-REG-03 | E3: Newyear (Yatichapat Kanta) | G3: Low | H3: Minor | I3: Open | J3: When confirmation does not match, "ตั้งรหัสผ่าน" stays enabled, while other rule failures disable it (inconsistent). | K3: 1. Reach set-password page 2. Password QaAuto12345, confirm QaAuto12345x | L3: Button disabled like other rule failures | M3: Button enabled; only inline "รหัสผ่านไม่ตรงกัน"; click does nothing | N3: =HYPERLINK("https://github.com/Yatichapat6510/empeo-registration-tests/blob/main/docs/exploration/23-password-mismatch.png","23-password-mismatch.png") | O3: UAT · Chromium · TH | P3: UX | Q3: Consistency
A4: BUG-03 | B4: 27/10/2026 | C4: Registration form | D4: TC-EDGE-01/02/03 | E4: Newyear (Yatichapat Kanta) | G4: Low | H4: Trivial | I4: Open | J4: Phone field accepts "-" and up to 15 characters; format error only on submit. | K4: 1. Type "-" or 15 digits in phone | L4: Only digits; length fits the selected country | M4: "-" accepted; 15 chars accepted | N4: =HYPERLINK("https://github.com/Yatichapat6510/empeo-registration-tests/blob/main/docs/exploration/16-phone-invalid.png","16-phone-invalid.png") | O4: UAT · Chromium · TH | P4: Validation | Q4: Input mask
A5: BUG-04 | B5: 27/10/2026 | C5: Promo code | D5: TC-PRM-04 | E5: Newyear (Yatichapat Kanta) | G5: Low | H5: Info | I5: Need clarification | J5: FREE15DAY is multi-use (usageCount > 3,000, isLock=false). Expected rule for a "reused promo code" is unclear. | K5: 1. Apply FREE15DAY in two sessions | L5: Per business rule (confirm with PO) | M5: Accepted both times | N5: =HYPERLINK("https://github.com/Yatichapat6510/empeo-registration-tests/blob/main/docs/exploration/10-promo-valid.png","10-promo-valid.png") | O5: UAT · Chromium · TH | P5: Requirement | Q5: Clarification
A6: BUG-05 | B6: 27/10/2026 | C6: Registration API | D6: TC-REG-01 | E6: Newyear (Yatichapat Kanta) | G6: Low | H6: Info | I6: Need clarification | J6: Same phone number can register many companies; no duplicate-phone block (duplicateInfo returns isDuplicate=false). | K6: 1. Register twice with phone 0967690708 | L6: Per business rule (confirm with PO) | M6: Both registrations reach OTP | N6: =HYPERLINK("https://github.com/Yatichapat6510/empeo-registration-tests/blob/main/docs/exploration/11-otp-page.png","11-otp-page.png") | O6: UAT · Chromium · TH | P6: Requirement | Q6: Clarification
A7: BUG-06 | B7: 27/10/2026 | C7: OTP → Set password | D7: TC-OTP-01, TC-OTP-03 | E7: Newyear (Yatichapat Kanta) | G7: Low | H7: Minor | I7: Observed (intermittent) | J7: After a correct OTP, the redirect to the set-password page sometimes takes more than 10 s on UAT. In the local run at 16:47, 2 of 35 tests failed on the 10 s wait although the page did open afterwards (see screenshot in the report). | K7: 1. Submit valid form 2. Enter OTP 123456 → ยืนยัน 3. Measure time until /create-password opens | L7: Set-password page opens within a few seconds | M7: Took > 10 s in 2 runs (UAT under load). Test wait raised to 30 s + 1 retry; reruns pass | N7: =HYPERLINK("https://github.com/Yatichapat6510/empeo-registration-tests/blob/main/docs/report/03-local-run-1647-otp01-failed.jpg","03-local-run-1647-otp01-failed.jpg") | O7: UAT · Chromium · TH | P7: Performance | Q7: Environment / UAT

Sheet Picture - Evidence
A1: # | B1: File (repo docs/) | C1: What it shows | D1: Link | E1: Preview
A2: 1 | B2: 01-register-form.png | C2: Registration form (default state) | D2: =HYPERLINK("https://github.com/Yatichapat6510/empeo-registration-tests/blob/main/docs/exploration/01-register-form.png","Open on GitHub") | E2: =IMAGE("https://raw.githubusercontent.com/Yatichapat6510/empeo-registration-tests/main/docs/exploration/01-register-form.png")
A3: 2 | B3: 02-empty-submit.png | C3: Required-field messages (TC-VAL-01) | D3: =HYPERLINK("https://github.com/Yatichapat6510/empeo-registration-tests/blob/main/docs/exploration/02-empty-submit.png","Open on GitHub") | E3: =IMAGE("https://raw.githubusercontent.com/Yatichapat6510/empeo-registration-tests/main/docs/exploration/02-empty-submit.png")
A4: 3 | B4: 08-promo-opened.png | C4: Promo field opened | D4: =HYPERLINK("https://github.com/Yatichapat6510/empeo-registration-tests/blob/main/docs/exploration/08-promo-opened.png","Open on GitHub") | E4: =IMAGE("https://raw.githubusercontent.com/Yatichapat6510/empeo-registration-tests/main/docs/exploration/08-promo-opened.png")
A5: 4 | B5: 09-promo-invalid.png | C5: Invalid promo message (TC-PRM-02) | D5: =HYPERLINK("https://github.com/Yatichapat6510/empeo-registration-tests/blob/main/docs/exploration/09-promo-invalid.png","Open on GitHub") | E5: =IMAGE("https://raw.githubusercontent.com/Yatichapat6510/empeo-registration-tests/main/docs/exploration/09-promo-invalid.png")
A6: 5 | B6: 10-promo-valid.png | C6: FREE15DAY applied (TC-PRM-01) | D6: =HYPERLINK("https://github.com/Yatichapat6510/empeo-registration-tests/blob/main/docs/exploration/10-promo-valid.png","Open on GitHub") | E6: =IMAGE("https://raw.githubusercontent.com/Yatichapat6510/empeo-registration-tests/main/docs/exploration/10-promo-valid.png")
A7: 6 | B7: 11-otp-page.png | C7: OTP dialog (TC-REG-01) | D7: =HYPERLINK("https://github.com/Yatichapat6510/empeo-registration-tests/blob/main/docs/exploration/11-otp-page.png","Open on GitHub") | E7: =IMAGE("https://raw.githubusercontent.com/Yatichapat6510/empeo-registration-tests/main/docs/exploration/11-otp-page.png")
A8: 7 | B8: 12-no-consent.png | C8: Consent not ticked – nothing happens (BUG-01) | D8: =HYPERLINK("https://github.com/Yatichapat6510/empeo-registration-tests/blob/main/docs/exploration/12-no-consent.png","Open on GitHub") | E8: =IMAGE("https://raw.githubusercontent.com/Yatichapat6510/empeo-registration-tests/main/docs/exploration/12-no-consent.png")
A9: 8 | B9: 13-otp-wrong.png | C9: Wrong OTP toast (TC-OTP-02) | D9: =HYPERLINK("https://github.com/Yatichapat6510/empeo-registration-tests/blob/main/docs/exploration/13-otp-wrong.png","Open on GitHub") | E9: =IMAGE("https://raw.githubusercontent.com/Yatichapat6510/empeo-registration-tests/main/docs/exploration/13-otp-wrong.png")
A10: 9 | B10: 14-otp-correct-filled.png | C10: OTP 123456 entered | D10: =HYPERLINK("https://github.com/Yatichapat6510/empeo-registration-tests/blob/main/docs/exploration/14-otp-correct-filled.png","Open on GitHub") | E10: =IMAGE("https://raw.githubusercontent.com/Yatichapat6510/empeo-registration-tests/main/docs/exploration/14-otp-correct-filled.png")
A11: 10 | B11: 15-success.png | C11: Set-password page after correct OTP | D11: =HYPERLINK("https://github.com/Yatichapat6510/empeo-registration-tests/blob/main/docs/exploration/15-success.png","Open on GitHub") | E11: =IMAGE("https://raw.githubusercontent.com/Yatichapat6510/empeo-registration-tests/main/docs/exploration/15-success.png")
A12: 11 | B12: 16-phone-invalid.png | C12: Invalid phone message (TC-EDGE-01) | D12: =HYPERLINK("https://github.com/Yatichapat6510/empeo-registration-tests/blob/main/docs/exploration/16-phone-invalid.png","Open on GitHub") | E12: =IMAGE("https://raw.githubusercontent.com/Yatichapat6510/empeo-registration-tests/main/docs/exploration/16-phone-invalid.png")
A13: 12 | B13: 17-create-password.png | C13: Set-password page | D13: =HYPERLINK("https://github.com/Yatichapat6510/empeo-registration-tests/blob/main/docs/exploration/17-create-password.png","Open on GitHub") | E13: =IMAGE("https://raw.githubusercontent.com/Yatichapat6510/empeo-registration-tests/main/docs/exploration/17-create-password.png")
A14: 13 | B14: 19-after-password.png | C14: "empeo พร้อมใช้งานแล้ว!" success screen | D14: =HYPERLINK("https://github.com/Yatichapat6510/empeo-registration-tests/blob/main/docs/exploration/19-after-password.png","Open on GitHub") | E14: =IMAGE("https://raw.githubusercontent.com/Yatichapat6510/empeo-registration-tests/main/docs/exploration/19-after-password.png")
A15: 14 | B15: 20-email-invalid.png | C15: Invalid e-mail message (TC-VAL-03) | D15: =HYPERLINK("https://github.com/Yatichapat6510/empeo-registration-tests/blob/main/docs/exploration/20-email-invalid.png","Open on GitHub") | E15: =IMAGE("https://raw.githubusercontent.com/Yatichapat6510/empeo-registration-tests/main/docs/exploration/20-email-invalid.png")
A16: 15 | B16: 21-email-dup-domain.png | C16: Duplicate domain message (TC-VAL-04) | D16: =HYPERLINK("https://github.com/Yatichapat6510/empeo-registration-tests/blob/main/docs/exploration/21-email-dup-domain.png","Open on GitHub") | E16: =IMAGE("https://raw.githubusercontent.com/Yatichapat6510/empeo-registration-tests/main/docs/exploration/21-email-dup-domain.png")
A17: 16 | B17: 22-otp-resent.png | C17: OTP resent, new ref (TC-OTP-06) | D17: =HYPERLINK("https://github.com/Yatichapat6510/empeo-registration-tests/blob/main/docs/exploration/22-otp-resent.png","Open on GitHub") | E17: =IMAGE("https://raw.githubusercontent.com/Yatichapat6510/empeo-registration-tests/main/docs/exploration/22-otp-resent.png")
A18: 17 | B18: 23-password-mismatch.png | C18: Password mismatch (BUG-02) | D18: =HYPERLINK("https://github.com/Yatichapat6510/empeo-registration-tests/blob/main/docs/exploration/23-password-mismatch.png","Open on GitHub") | E18: =IMAGE("https://raw.githubusercontent.com/Yatichapat6510/empeo-registration-tests/main/docs/exploration/23-password-mismatch.png")
A19: 18 | B19: report/01-html-report-summary.jpg | C19: HTML report – 35/35 passed (video run 16:08) | D19: =HYPERLINK("https://github.com/Yatichapat6510/empeo-registration-tests/blob/main/docs/report/01-html-report-summary.jpg","Open on GitHub") | E19: =IMAGE("https://raw.githubusercontent.com/Yatichapat6510/empeo-registration-tests/main/docs/report/01-html-report-summary.jpg")
A20: 19 | B20: report/02-tc-reg-01-steps.jpg | C20: HTML report – TC-REG-01 steps, final screenshot, trace and video | D20: =HYPERLINK("https://github.com/Yatichapat6510/empeo-registration-tests/blob/main/docs/report/02-tc-reg-01-steps.jpg","Open on GitHub") | E20: =IMAGE("https://raw.githubusercontent.com/Yatichapat6510/empeo-registration-tests/main/docs/report/02-tc-reg-01-steps.jpg")
A21: 20 | B21: report/03-local-run-1647-otp01-failed.jpg | C21: HTML report – run 16:47, TC-OTP-01 failed on 10 s wait; page did open (BUG-06) | D21: =HYPERLINK("https://github.com/Yatichapat6510/empeo-registration-tests/blob/main/docs/report/03-local-run-1647-otp01-failed.jpg","Open on GitHub") | E21: =IMAGE("https://raw.githubusercontent.com/Yatichapat6510/empeo-registration-tests/main/docs/report/03-local-run-1647-otp01-failed.jpg")
A22: 21 | B22: submission/00-submission-card.jpg | C22: Submission card (summary + links) | D22: =HYPERLINK("https://github.com/Yatichapat6510/empeo-registration-tests/blob/main/docs/submission/00-submission-card.jpg","Open on GitHub") | E22: =IMAGE("https://raw.githubusercontent.com/Yatichapat6510/empeo-registration-tests/main/docs/submission/00-submission-card.jpg")
B24: Videos and folders
B25: Headed run, screen recording (Drive / Video) | D25: =HYPERLINK("https://drive.google.com/file/d/15qjjIL-YVDhUihsYCpx1IiIzDr7kI9Cy/view","Open")
B26: Playwright recording of all 35 tests, 8 min (GitHub) | D26: =HYPERLINK("https://github.com/Yatichapat6510/empeo-registration-tests/blob/main/docs/demo/automation-run.mp4","Open")
B27: Drive folder (workbook, Evident Photo, Video) | D27: =HYPERLINK("https://drive.google.com/drive/folders/1X-i7e-JlTXuE6q1Cv5BMVRRIkGONhn_q","Open")
B28: GitHub repository | D28: =HYPERLINK("https://github.com/Yatichapat6510/empeo-registration-tests","Open")
